Workbook

Sheet MaxLFQ_Intensities_processed
A1: Protein.Group | B1: Protein.Names | C1: Genes | D1: max_PG.Q.val | E1: max_pep | F1: max_proteotypic_pep | G1: max_shared_pep | H1: max_digested_peptides | I1: ATG18_2_1 | J1: ATG18_2_2 | K1: ATG18_2_3 | L1: ATG18_3_1 | M1: ATG18_3_2 | N1: ATG18_3_3 | O1: ATG18_4_1 | P1: ATG18_4_2 | Q1: ATG18_4_3 | R1: ATG18_5_1 | S1: ATG18_5_2 | T1: ATG18_5_3 | U1: B11_3_1 | V1: B11_3_2 | W1: B11_3_3 | X1: B11_4_1 | Y1: B11_4_2 | Z1: B11_4_3 | AA1: B11_5_1 | AB1: B11_5_2 | AC1: B11_5_3 | AD1: Sparklines | AE1: TTEST ATG18 vs B11 | AF1: RANK ATG18 vs B11 | AG1: LOG2_RATIO ATG18 vs B11 | AH1: No of replicates ATG18 vs B11 | AI1: BH ADJ ATG18 vs B11 | AJ1: SIGNIFICANT BH ATG18 vs B11 | AK1: SIGNIFICANT BH LOG2 Filter ATG18 vs B11 | AL1: ATG18 sum | AM1: B11 sum | AN1: ATG18 percentage | AO1: B11 percentage | AP1: FC | AQ1: log2FC | AR1: p-value -LogFC | AT1: log * log
A2: C6KTE2 | B2: C6KTE2_PLAF7 | C2: PF3D7_0630700 | D2: 0.014190317 | E2: 4 | F2: 4 | G2: 0 | H2: 107 | I2: 1547.6488 | J2: 2127.1147 | K2: 1654.5514 | L2: 746.1438 | M2: 1032.197 | N2: 1119.5284 | O2: 1265.2539 | P2: 1573.5155 | Q2: 1283.6354 | R2: 1227.1829 | S2: 1690.077 | T2: 1271.6576 | AE2: 0 | AF2: 1 | AG2: 13.750507 | AH2: 12 | AI2: 0 | AJ2: 0 | AK2: sig. enriched in ATG18 | AL2: =SUM(I2:T2) -> 16538.506 | AM2: =SUM(U2:AC2) -> 0 | AN2: =AL2/#REF!*100 -> #REF! | AO2: =AM2/#REF!*100 -> #REF! | AP2: =AN2/AO2 -> #REF! | AQ2: =LOG(AP2,2) -> #REF! | AR2: =-LOG(AE2,10) -> #NUM! | AT2: =-LOG(AE2, 10)*AG2 -> #NUM!
A3: Q8I347 | B3: Q8I347_PLAF7 | C3: PF3D7_0910500 | D3: 0.054697722 | E3: 2 | F3: 2 | G3: 0 | H3: 266 | I3: 986.90692 | J3: 2214.3635 | K3: 907.39264 | L3: 833.92487 | M3: 600.62268 | N3: 696.68597 | O3: 1936.5459 | P3: 2222.7166 | Q3: 1301.3213 | R3: 1920.045 | S3: 1913.1294 | T3: 1261.9792 | AE3: 0 | AF3: 1 | AG3: 13.772764 | AH3: 12 | AI3: 0 | AJ3: 0 | AK3: sig. enriched in ATG18 | AL3: =SUM(I3:T3) -> 16795.634 | AM3: =SUM(U3:AC3) -> 0 | AN3: =AL3/#REF!*100 -> #REF! | AO3: =AM3/#REF!*100 -> #REF! | AP3: =AN3/AO3 -> #REF! | AQ3: =LOG(AP3,2) -> #REF! | AR3: =-LOG(AE3,10) -> #NUM! | AT3: =-LOG(AE3, 10)*AG3 -> #NUM!
A4: Q8I3G4 | B4: Q8I3G4_PLAF7 | C4: PF3D7_0530400 | D4: 0.015013536 | E4: 3 | F4: 3 | G4: 0 | H4: 227 | I4: 1184.8727 | J4: 858.31842 | K4: 1239.3157 | L4: 783.27789 | M4: 1112.8248 | N4: 427.06732 | O4: 2453.6196 | P4: 1271.2858 | Q4: 3277.1448 | R4: 915.88593 | S4: 2618.0811 | T4: 1773.1058 | AE4: 0 | AF4: 1 | AG4: 13.86583 | AH4: 12 | AI4: 0 | AJ4: 0 | AK4: sig. enriched in ATG18 | AL4: =SUM(I4:T4) -> 17914.8 | AM4: =SUM(U4:AC4) -> 0 | AN4: =AL4/#REF!*100 -> #REF! | AO4: =AM4/#REF!*100 -> #REF! | AP4: =AN4/AO4 -> #REF! | AQ4: =LOG(AP4,2) -> #REF! | AR4: =-LOG(AE4,10) -> #NUM! | AT4: =-LOG(AE4, 10)*AG4 -> #NUM!
A5: Q8IJD9 | B5: Q8IJD9_PLAF7 | C5: PF3D7_1026200 | D5: 0.047084004 | E5: 2 | F5: 2 | G5: 0 | H5: 89 | I5: 1292.2228 | J5: 1080.2239 | K5: 1020.7233 | N5: 867.99994 | O5: 2175.6841 | Q5: 1613.9073 | R5: 1689.021 | S5: 3290.1335 | T5: 1192.4362 | AE5: 0 | AF5: 1 | AG5: 13.947876 | AH5: 9 | AI5: 0 | AJ5: 0 | AK5: sig. enriched in ATG18 | AL5: =SUM(I5:T5) -> 14222.352 | AM5: =SUM(U5:AC5) -> 0 | AN5: =AL5/#REF!*100 -> #REF! | AO5: =AM5/#REF!*100 -> #REF! | AP5: =AN5/AO5 -> #REF! | AQ5: =LOG(AP5,2) -> #REF! | AR5: =-LOG(AE5,10) -> #NUM! | AT5: =-LOG(AE5, 10)*AG5 -> #NUM!
A6: Q25811 | B6: Q25811_PLAF7 | C6: rps17 | D6: 0.05550307 | E6: 2 | F6: 2 | G6: 0 | H6: 15 | I6: 1308.813 | J6: 1198.819 | K6: 1103.3928 | L6: 435.11072 | M6: 0 | O6: 1550.369 | P6: 1998.1327 | Q6: 1565.3162 | R6: 1888.2422 | S6: 2282.4612 | T6: 2472.3455 | AE6: 0 | AF6: 1 | AG6: 13.947911 | AH6: 10 | AI6: 0 | AJ6: 0 | AK6: sig. enriched in ATG18 | AL6: =SUM(I6:T6) -> 15803.002 | AM6: =SUM(U6:AC6) -> 0 | AN6: =AL6/#REF!*100 -> #REF! | AO6: =AM6/#REF!*100 -> #REF! | AP6: =AN6/AO6 -> #REF! | AQ6: =LOG(AP6,2) -> #REF! | AR6: =-LOG(AE6,10) -> #NUM! | AT6: =-LOG(AE6, 10)*AG6 -> #NUM!
A7: Q9U0H4 | B7: Q9U0H4_PLAF7 | C7: PF3D7_0411400 | D7: 0.081559435 | E7: 3 | F7: 3 | G7: 0 | H7: 201 | I7: 1342.274 | J7: 2176.0674 | K7: 1500.8392 | L7: 1204.3801 | M7: 2275.3589 | N7: 1571.042 | O7: 0 | P7: 0 | Q7: 0 | R7: 1166.2814 | S7: 1899.0734 | T7: 1241.9327 | AE7: 0 | AF7: 1 | AG7: 13.963503 | AH7: 9 | AI7: 0 | AJ7: 0 | AK7: sig. enriched in ATG18 | AL7: =SUM(I7:T7) -> 14377.249 | AM7: =SUM(U7:AC7) -> 0 | AN7: =AL7/#REF!*100 -> #REF! | AO7: =AM7/#REF!*100 -> #REF! | AP7: =AN7/AO7 -> #REF! | AQ7: =LOG(AP7,2) -> #REF! | AR7: =-LOG(AE7,10) -> #NUM! | AT7: =-LOG(AE7, 10)*AG7 -> #NUM!
A8: Q8IL99 | B8: Q8IL99_PLAF7 | C8: PF3D7_1436700 | D8: 0.018161805 | E8: 4 | F8: 4 | G8: 0 | H8: 133 | I8: 1483.6587 | J8: 1727.1826 | K8: 1550.845 | M8: 455.57941 | O8: 1400.51 | P8: 1378.5566 | Q8: 1716.5544 | R8: 3232.3154 | S8: 1919.9175 | T8: 1424.254 | AE8: 0 | AF8: 1 | AG8: 13.991644 | AH8: 10 | AI8: 0 | AJ8: 0 | AK8: sig. enriched in ATG18 | AL8: =SUM(I8:T8) -> 16289.374 | AM8: =SUM(U8:AC8) -> 0 | AN8: =AL8/#REF!*100 -> #REF! | AO8: =AM8/#REF!*100 -> #REF! | AP8: =AN8/AO8 -> #REF! | AQ8: =LOG(AP8,2) -> #REF! | AR8: =-LOG(AE8,10) -> #NUM! | AT8: =-LOG(AE8, 10)*AG8 -> #NUM!
A9: A0A5K1K9F2 | B9: A0A5K1K9F2_PLAF7 | C9: PF3D7_1333900 | D9: 0.027517887 | E9: 3 | F9: 3 | G9: 0 | H9: 186 | J9: 2643.3743 | K9: 826.39972 | L9: 894.60089 | M9: 1073.2865 | O9: 2289.0942 | P9: 1979.7184 | Q9: 2033.535 | R9: 2351.2324 | S9: 2185.9666 | T9: 2128.2642 | AE9: 0 | AF9: 1 | AG9: 14.167847 | AH9: 10 | AI9: 0 | AJ9: 0 | AK9: sig. enriched in ATG18 | AL9: =SUM(I9:T9) -> 18405.472 | AM9: =SUM(U9:AC9) -> 0 | AN9: =AL9/#REF!*100 -> #REF! | AO9: =AM9/#REF!*100 -> #REF! | AP9: =AN9/AO9 -> #REF! | AQ9: =LOG(AP9,2) -> #REF! | AR9: =-LOG(AE9,10) -> #NUM! | AT9: =-LOG(AE9, 10)*AG9 -> #NUM!
A10: O77338 | B10: O77338_PLAF7 | C10: PF3D7_0313500 | D10: 0.015958752 | E10: 4 | F10: 4 | G10: 0 | H10: 138 | I10: 2047.3318 | J10: 2563.5801 | K10: 1753.3335 | L10: 1237.9075 | M10: 1950.9299 | N10: 688.67627 | O10: 1351.285 | P10: 2083.7917 | Q10: 2629.9883 | R10: 2554.2603 | S10: 1591.5695 | T10: 2604.5955 | AE10: 0 | AF10: 1 | AG10: 14.229898 | AH10: 12 | AI10: 0 | AJ10: 0 | AK10: sig. enriched in ATG18 | AL10: =SUM(I10:T10) -> 23057.249 | AM10: =SUM(U10:AC10) -> 0 | AN10: =AL10/#REF!*100 -> #REF! | AO10: =AM10/#REF!*100 -> #REF! | AP10: =AN10/AO10 -> #REF! | AQ10: =LOG(AP10,2) -> #REF! | AR10: =-LOG(AE10,10) -> #NUM! | AT10: =-LOG(AE10, 10)*AG10 -> #NUM!
A11: A0A5K1K8W6 | B11: A0A5K1K8W6_PLAF7 | C11: PF3D7_1339600 | D11: 0.021917809 | E11: 5 | F11: 5 | G11: 0 | H11: 101 | I11: 1053.4846 | J11: 1508.0621 | K11: 1175.7411 | M11: 566.37885 | O11: 2295.1455 | P11: 1454.0392 | Q11: 2046.2462 | R11: 3363.3643 | S11: 1906.5281 | T11: 4454.5718 | AE11: 0 | AF11: 1 | AG11: 14.274929 | AH11: 10 | AI11: 0 | AJ11: 0 | AK11: sig. enriched in ATG18 | AL11: =SUM(I11:T11) -> 19823.562 | AM11: =SUM(U11:AC11) -> 0 | AN11: =AL11/#REF!*100 -> #REF! | AO11: =AM11/#REF!*100 -> #REF! | AP11: =AN11/AO11 -> #REF! | AQ11: =LOG(AP11,2) -> #REF! | AR11: =-LOG(AE11,10) -> #NUM! | AT11: =-LOG(AE11, 10)*AG11 -> #NUM!
A12: O97265 | B12: O97265_PLAF7 | C12: PF3D7_0315000 | D12: 0.048715204 | E12: 2 | F12: 2 | G12: 0 | H12: 32 | I12: 1599.77 | J12: 2226.7524 | K12: 1621.1984 | L12: 478.11774 | O12: 2322.1184 | P12: 2792.9639 | Q12: 2348.9612 | R12: 1679.8026 | S12: 2826.3901 | T12: 1953.7151 | AE12: 0 | AF12: 1 | AG12: 14.276836 | AH12: 10 | AI12: 0 | AJ12: 0 | AK12: sig. enriched in ATG18 | AL12: =SUM(I12:T12) -> 19849.79 | AM12: =SUM(U12:AC12) -> 0 | AN12: =AL12/#REF!*100 -> #REF! | AO12: =AM12/#REF!*100 -> #REF! | AP12: =AN12/AO12 -> #REF! | AQ12: =LOG(AP12,2) -> #REF! | AR12: =-LOG(AE12,10) -> #NUM! | AT12: =-LOG(AE12, 10)*AG12 -> #NUM!
A13: A0A5K1K9E4 | B13: A0A5K1K9E4_PLAF7 | C13: PF3D7_0525600 | D13: 0.045250066 | E13: 2 | F13: 2 | G13: 0 | H13: 56 | I13: 2799.0664 | J13: 1479.8552 | K13: 1795.5488 | M13: 837.44574 | O13: 1798.8931 | Q13: 974.72925 | R13: 3685.1895 | S13: 2390.4087 | T13: 2258.1536 | AE13: 0 | AF13: 1 | AG13: 14.289258 | AH13: 9 | AI13: 0 | AJ13: 0 | AK13: sig. enriched in ATG18 | AL13: =SUM(I13:T13) -> 18019.29 | AM13: =SUM(U13:AC13) -> 0 | AN13: =AL13/#REF!*100 -> #REF! | AO13: =AM13/#REF!*100 -> #REF! | AP13: =AN13/AO13 -> #REF! | AQ13: =LOG(AP13,2) -> #REF! | AR13: =-LOG(AE13,10) -> #NUM! | AT13: =-LOG(AE13, 10)*AG13 -> #NUM!
A14: Q8IDG0 | B14: Q8IDG0_PLAF7 | C14: PF3D7_1354100 | D14: 0.037424058 | E14: 3 | F14: 3 | G14: 0 | H14: 52 | I14: 1817.874 | J14: 2391.772 | K14: 1836.6853 | L14: 2507.0813 | M14: 2686.0286 | N14: 845.44196 | O14: 1842.1826 | P14: 1504.476 | Q14: 2435.8865 | R14: 2682.9802 | S14: 1785.001 | T14: 2289.0945 | AE14: 0 | AF14: 1 | AG14: 14.324773 | AH14: 12 | AI14: 0 | AJ14: 0 | AK14: sig. enriched in ATG18 | AL14: =SUM(I14:T14) -> 24624.504 | AM14: =SUM(U14:AC14) -> 0 | AN14: =AL14/#REF!*100 -> #REF! | AO14: =AM14/#REF!*100 -> #REF! | AP14: =AN14/AO14 -> #REF! | AQ14: =LOG(AP14,2) -> #REF! | AR14: =-LOG(AE14,10) -> #NUM! | AT14: =-LOG(AE14, 10)*AG14 -> #NUM!
A15: Q8IC19 | B15: YPF13_PLAF7 | C15: PF3D7_0705100 | D15: 0.011691542 | E15: 5 | F15: 5 | G15: 0 | H15: 141 | K15: 1820.6805 | L15: 2171.9929 | M15: 2731.7898 | N15: 1477.637 | O15: 2274.6377 | P15: 2008.9713 | Q15: 2498.4863 | R15: 2116.2402 | S15: 2807.553 | T15: 2314.251 | AE15: 0 | AF15: 1 | AG15: 14.439717 | AH15: 10 | AI15: 0 | AJ15: 0 | AK15: sig. enriched in ATG18 | AL15: =SUM(I15:T15) -> 22222.24 | AM15: =SUM(U15:AC15) -> 0 | AN15: =AL15/#REF!*100 -> #REF! | AO15: =AM15/#REF!*100 -> #REF! | AP15: =AN15/AO15 -> #REF! | AQ15: =LOG(AP15,2) -> #REF! | AR15: =-LOG(AE15,10) -> #NUM! | AT15: =-LOG(AE15, 10)*AG15 -> #NUM!
A16: Q8I5W3 | B16: Q8I5W3_PLAF7 | C16: PF3D7_1208500 | D16: 0.00031979533 | E16: 6 | F16: 6 | G16: 0 | H16: 250 | I16: 1825.0005 | J16: 2359.7146 | K16: 2382.5464 | L16: 1872.2804 | M16: 2240.8098 | N16: 1504.2953 | O16: 2033.2959 | P16: 2599.854 | Q16: 2294.917 | R16: 2758.1011 | S16: 3162.0908 | T16: 1850.5818 | AE16: 0 | AF16: 1 | AG16: 14.451398 | AH16: 12 | AI16: 0 | AJ16: 0 | AK16: sig. enriched in ATG18 | AL16: =SUM(I16:T16) -> 26883.488 | AM16: =SUM(U16:AC16) -> 0 | AN16: =AL16/#REF!*100 -> #REF! | AO16: =AM16/#REF!*100 -> #REF! | AP16: =AN16/AO16 -> #REF! | AQ16: =LOG(AP16,2) -> #REF! | AR16: =-LOG(AE16,10) -> #NUM! | AT16: =-LOG(AE16, 10)*AG16 -> #NUM!
A17: A0A143ZYR7;Q8IJB4 | B17: A0A143ZYR7_PLAF7;Q8IJB4_PLAF7 | C17: PF3D7_1029100.1;PF3D7_1029100.2 | D17: 0.064541213 | E17: 2 | F17: 0 | G17: 2 | H17: 201 | I17: 3224.196 | J17: 953.12463 | K17: 1382.8352 | M17: 998.1438 | N17: 208.36287 | O17: 1853.8854 | P17: 3693.8293 | Q17: 3752.417 | R17: 2512.5286 | S17: 2879.3567 | T17: 3246.4561 | AE17: 0 | AF17: 1 | AG17: 14.45502 | AH17: 11 | AI17: 0 | AJ17: 0 | AK17: sig. enriched in ATG18 | AL17: =SUM(I17:T17) -> 24705.136 | AM17: =SUM(U17:AC17) -> 0 | AN17: =AL17/#REF!*100 -> #REF! | AO17: =AM17/#REF!*100 -> #REF! | AP17: =AN17/AO17 -> #REF! | AQ17: =LOG(AP17,2) -> #REF! | AR17: =-LOG(AE17,10) -> #NUM! | AT17: =-LOG(AE17, 10)*AG17 -> #NUM!
A18: Q8I634 | B18: Q8I634_PLAF7 | C18: PF3D7_1201100 | D18: 0.0042666667 | E18: 4 | F18: 4 | G18: 0 | H18: 122 | I18: 1645.0852 | J18: 2121.259 | K18: 1776.4705 | L18: 1655.0945 | M18: 1372.8546 | O18: 2551.4468 | P18: 2622.9041 | Q18: 4075.0596 | R18: 2292.1472 | S18: 2632.4126 | AE18: 0 | AF18: 1 | AG18: 14.473245 | AH18: 10 | AI18: 0 | AJ18: 0 | AK18: sig. enriched in ATG18 | AL18: =SUM(I18:T18) -> 22744.734 | AM18: =SUM(U18:AC18) -> 0 | AN18: =AL18/#REF!*100 -> #REF! | AO18: =AM18/#REF!*100 -> #REF! | AP18: =AN18/AO18 -> #REF! | AQ18: =LOG(AP18,2) -> #REF! | AR18: =-LOG(AE18,10) -> #NUM! | AT18: =-LOG(AE18, 10)*AG18 -> #NUM!
A19: O96225 | B19: O96225_PLAF7 | C19: PF3D7_0214500 | D19: 0.047199048 | E19: 2 | F19: 2 | G19: 0 | H19: 52 | J19: 1829.1434 | K19: 2098.5295 | N19: 600.06458 | O19: 2307.8977 | P19: 4109.6763 | Q19: 2529.7327 | R19: 2006.1532 | S19: 3432.4065 | T19: 2695.3511 | AE19: 0 | AF19: 1 | AG19: 14.551345 | AH19: 9 | AI19: 0 | AJ19: 0 | AK19: sig. enriched in ATG18 | AL19: =SUM(I19:T19) -> 21608.955 | AM19: =SUM(U19:AC19) -> 0 | AN19: =AL19/#REF!*100 -> #REF! | AO19: =AM19/#REF!*100 -> #REF! | AP19: =AN19/AO19 -> #REF! | AQ19: =LOG(AP19,2) -> #REF! | AR19: =-LOG(AE19,10) -> #NUM! | AT19: =-LOG(AE19, 10)*AG19 -> #NUM!
A20: A0A144A1F0 | B20: A0A144A1F0_PLAF7 | C20: PF3D7_1019300 | D20: 0.015052685 | E20: 12 | F20: 12 | G20: 0 | H20: 225 | I20: 2352.3081 | J20: 2723.2986 | K20: 2280.9829 | L20: 3017.8608 | M20: 4086.8337 | N20: 2078.6492 | O20: 2462.9417 | P20: 2300.0046 | Q20: 2407.3572 | R20: 1604.7815 | S20: 2279.1177 | T20: 1430.6555 | AE20: 0 | AF20: 1 | AG20: 14.561964 | AH20: 12 | AI20: 0 | AJ20: 0 | AK20: sig. enriched in ATG18 | AL20: =SUM(I20:T20) -> 29024.792 | AM20: =SUM(U20:AC20) -> 0 | AN20: =AL20/#REF!*100 -> #REF! | AO20: =AM20/#REF!*100 -> #REF! | AP20: =AN20/AO20 -> #REF! | AQ20: =LOG(AP20,2) -> #REF! | AR20: =-LOG(AE20,10) -> #NUM! | AT20: =-LOG(AE20, 10)*AG20 -> #NUM!
A21: Q8I335 | B21: GUF1_PLAF7 | C21: PF3D7_0911700 | D21: 0.0033290654 | E21: 4 | F21: 4 | G21: 0 | H21: 184 | I21: 3130.9375 | J21: 1912.7875 | K21: 2330.2295 | L21: 1239.7299 | M21: 1649.4249 | N21: 672.56085 | O21: 3261.9109 | P21: 0 | Q21: 3800.9382 | R21: 2192.3604 | S21: 5052.6797 | T21: 2078.7871 | AE21: 0 | AF21: 1 | AG21: 14.60029 | AH21: 11 | AI21: 0 | AJ21: 0 | AK21: sig. enriched in ATG18 | AL21: =SUM(I21:T21) -> 27322.346 | AM21: =SUM(U21:AC21) -> 0 | AN21: =AL21/#REF!*100 -> #REF! | AO21: =AM21/#REF!*100 -> #REF! | AP21: =AN21/AO21 -> #REF! | AQ21: =LOG(AP21,2) -> #REF! | AR21: =-LOG(AE21,10) -> #NUM! | AT21: =-LOG(AE21, 10)*AG21 -> #NUM!
A22: A0A5K1K8X3 | B22: A0A5K1K8X3_PLAF7 | C22: PF3D7_1342200 | D22: 0.025031606 | E22: 5 | F22: 5 | G22: 0 | H22: 156 | I22: 2793.2559 | J22: 1653.6039 | K22: 1458.0575 | L22: 1252.5774 | O22: 3333.7366 | P22: 3670.6953 | Q22: 2140.1885 | R22: 2262.2488 | S22: 4171.9272 | T22: 2440.4175 | AE22: 0 | AF22: 1 | AG22: 14.619802 | AH22: 10 | AI22: 0 | AJ22: 0 | AK22: sig. enriched in ATG18 | AL22: =SUM(I22:T22) -> 25176.708 | AM22: =SUM(U22:AC22) -> 0 | AN22: =AL22/#REF!*100 -> #REF! | AO22: =AM22/#REF!*100 -> #REF! | AP22: =AN22/AO22 -> #REF! | AQ22: =LOG(AP22,2) -> #REF! | AR22: =-LOG(AE22,10) -> #NUM! | AT22: =-LOG(AE22, 10)*AG22 -> #NUM!
A23: O96170 | B23: O96170_PLAF7 | C23: PF3D7_0208300 | D23: 0.03567889 | E23: 2 | F23: 2 | G23: 0 | H23: 282 | I23: 3034.7625 | J23: 2973.0063 | K23: 1732.0862 | L23: 1753.1809 | M23: 2894.6929 | N23: 1581.923 | O23: 2963.9707 | P23: 2816.658 | Q23: 3417.4949 | R23: 3089.2915 | S23: 2298.1472 | T23: 1976.7698 | AE23: 0 | AF23: 1 | AG23: 14.634999 | AH23: 12 | AI23: 0 | AJ23: 0 | AK23: sig. enriched in ATG18 | AL23: =SUM(I23:T23) -> 30531.984 | AM23: =SUM(U23:AC23) -> 0 | AN23: =AL23/#REF!*100 -> #REF! | AO23: =AM23/#REF!*100 -> #REF! | AP23: =AN23/AO23 -> #REF! | AQ23: =LOG(AP23,2) -> #REF! | AR23: =-LOG(AE23,10) -> #NUM! | AT23: =-LOG(AE23, 10)*AG23 -> #NUM!
A24: A0A143ZYI9 | B24: A0A143ZYI9_PLAF7 | C24: PF3D7_1135500 | D24: 0.088649943 | E24: 3 | F24: 3 | G24: 0 | H24: 58 | I24: 2718.0483 | J24: 3474.863 | K24: 1285.5448 | L24: 783.05945 | M24: 1317.1674 | O24: 3741.1189 | P24: 3098.5073 | Q24: 1035.4331 | R24: 3344.8723 | S24: 3553.3745 | T24: 3765.1145 | AE24: 0 | AF24: 1 | AG24: 14.641657 | AH24: 11 | AI24: 0 | AJ24: 0 | AK24: sig. enriched in ATG18 | AL24: =SUM(I24:T24) -> 28117.104 | AM24: =SUM(U24:AC24) -> 0 | AN24: =AL24/#REF!*100 -> #REF! | AO24: =AM24/#REF!*100 -> #REF! | AP24: =AN24/AO24 -> #REF! | AQ24: =LOG(AP24,2) -> #REF! | AR24: =-LOG(AE24,10) -> #NUM! | AT24: =-LOG(AE24, 10)*AG24 -> #NUM!
A25: Q8I2E1 | B25: Q8I2E1_PLAF7 | C25: PF3D7_0113700 | D25: 0.052197069 | E25: 4 | F25: 4 | G25: 0 | H25: 56 | I25: 1140.4636 | J25: 1581.5675 | L25: 1141.5111 | O25: 3326.4773 | P25: 4894.688 | Q25: 1912.4006 | R25: 3218.9304 | S25: 3492.6716 | T25: 2452.8015 | AE25: 0 | AF25: 1 | AG25: 14.651445 | AH25: 9 | AI25: 0 | AJ25: 0 | AK25: sig. enriched in ATG18 | AL25: =SUM(I25:T25) -> 23161.512 | AM25: =SUM(U25:AC25) -> 0 | AN25: =AL25/#REF!*100 -> #REF! | AO25: =AM25/#REF!*100 -> #REF! | AP25: =AN25/AO25 -> #REF! | AQ25: =LOG(AP25,2) -> #REF! | AR25: =-LOG(AE25,10) -> #NUM! | AT25: =-LOG(AE25, 10)*AG25 -> #NUM!
A26: Q8IHV8 | B26: Q8IHV8_PLAF7 | C26: PF3D7_1140700 | D26: 0.086905323 | E26: 3 | F26: 3 | G26: 0 | H26: 311 | I26: 2287.9128 | J26: 3677.9797 | K26: 2469.9004 | L26: 1722.9215 | M26: 1487.8391 | N26: 1716.1145 | O26: 3966.4336 | P26: 3007.4802 | Q26: 2841.1165 | R26: 2209.1287 | S26: 3679.2322 | T26: 2089.127 | AE26: 0 | AF26: 1 | AG26: 14.66415 | AH26: 12 | AI26: 0 | AJ26: 0 | AK26: sig. enriched in ATG18 | AL26: =SUM(I26:T26) -> 31155.186 | AM26: =SUM(U26:AC26) -> 0 | AN26: =AL26/#REF!*100 -> #REF! | AO26: =AM26/#REF!*100 -> #REF! | AP26: =AN26/AO26 -> #REF! | AQ26: =LOG(AP26,2) -> #REF! | AR26: =-LOG(AE26,10) -> #NUM! | AT26: =-LOG(AE26, 10)*AG26 -> #NUM!
A27: Q8I3Y1 | B27: Q8I3Y1_PLAF7 | C27: PF3D7_0512500 | D27: 0.047925033 | E27: 4 | F27: 4 | G27: 0 | H27: 113 | I27: 3313.5449 | J27: 3286.1731 | K27: 1361.7554 | L27: 1491.4852 | M27: 1188.7051 | N27: 1049.9473 | O27: 3096.0522 | P27: 2967.5129 | Q27: 2645.4924 | R27: 3641.553 | S27: 4084.6619 | T27: 3468.1572 | AE27: 0 | AF27: 1 | AG27: 14.684376 | AH27: 12 | AI27: 0 | AJ27: 0 | AK27: sig. enriched in ATG18 | AL27: =SUM(I27:T27) -> 31595.041 | AM27: =SUM(U27:AC27) -> 0 | AN27: =AL27/#REF!*100 -> #REF! | AO27: =AM27/#REF!*100 -> #REF! | AP27: =AN27/AO27 -> #REF! | AQ27: =LOG(AP27,2) -> #REF! | AR27: =-LOG(AE27,10) -> #NUM! | AT27: =-LOG(AE27, 10)*AG27 -> #NUM!
A28: Q9U0L6 | B28: Q9U0L6_PLAF7 | C28: PF3D7_0407000 | D28: 0.0033290654 | E28: 5 | F28: 5 | G28: 0 | H28: 63 | I28: 2955.3545 | J28: 3099.4775 | K28: 2661.707 | L28: 2020.8945 | M28: 2544.2019 | N28: 1823.9155 | O28: 3528.9329 | P28: 2649.9966 | Q28: 3261.4795 | R28: 2122.8452 | S28: 2467.093 | T28: 3088.1875 | AE28: 0 | AF28: 1 | AG28: 14.712817 | AH28: 12 | AI28: 0 | AJ28: 0 | AK28: sig. enriched in ATG18 | AL28: =SUM(I28:T28) -> 32224.086 | AM28: =SUM(U28:AC28) -> 0 | AN28: =AL28/#REF!*100 -> #REF! | AO28: =AM28/#REF!*100 -> #REF! | AP28: =AN28/AO28 -> #REF! | AQ28: =LOG(AP28,2) -> #REF! | AR28: =-LOG(AE28,10) -> #NUM! | AT28: =-LOG(AE28, 10)*AG28 -> #NUM!
A29: C0H499 | B29: C0H499_PLAF7 | C29: PF3D7_0408400 | D29: 0.029102668 | E29: 2 | F29: 2 | G29: 0 | H29: 85 | I29: 2261.4548 | J29: 1915.944 | K29: 2094.0571 | M29: 1048.3807 | O29: 2855.7493 | P29: 3800.9844 | Q29: 1799.2655 | R29: 3390.7466 | S29: 4588.0415 | T29: 3106.8604 | AE29: 0 | AF29: 1 | AG29: 14.713251 | AH29: 10 | AI29: 0 | AJ29: 0 | AK29: sig. enriched in ATG18 | AL29: =SUM(I29:T29) -> 26861.484 | AM29: =SUM(U29:AC29) -> 0 | AN29: =AL29/#REF!*100 -> #REF! | AO29: =AM29/#REF!*100 -> #REF! | AP29: =AN29/AO29 -> #REF! | AQ29: =LOG(AP29,2) -> #REF! | AR29: =-LOG(AE29,10) -> #NUM! | AT29: =-LOG(AE29, 10)*AG29 -> #NUM!
A30: Q8II20 | B30: Q8II20_PLAF7 | C30: PF3D7_1134400 | D30: 0.0015965939 | E30: 3 | F30: 3 | G30: 0 | H30: 29 | I30: 1990.5823 | J30: 2508.7803 | K30: 1933.5654 | O30: 4021.5474 | P30: 1984.5575 | Q30: 3031.3599 | R30: 2473.2244 | S30: 3054.499 | T30: 3569.1704 | AE30: 0 | AF30: 1 | AG30: 14.736454 | AH30: 9 | AI30: 0 | AJ30: 0 | AK30: sig. enriched in ATG18 | AL30: =SUM(I30:T30) -> 24567.286 | AM30: =SUM(U30:AC30) -> 0 | AN30: =AL30/#REF!*100 -> #REF! | AO30: =AM30/#REF!*100 -> #REF! | AP30: =AN30/AO30 -> #REF! | AQ30: =LOG(AP30,2) -> #REF! | AR30: =-LOG(AE30,10) -> #NUM! | AT30: =-LOG(AE30, 10)*AG30 -> #NUM!
A31: C0H4V3 | B31: C0H4V3_PLAF7 | C31: PF3D7_0817400 | D31: 0.050702214 | E31: 2 | F31: 2 | G31: 0 | H31: 94 | I31: 2337.7795 | J31: 3279.2227 | K31: 1794.1052 | L31: 893.60895 | M31: 1200.2 | O31: 3293.2053 | P31: 3194.9944 | Q31: 2957.2712 | R31: 4348.3994 | S31: 4180.3042 | T31: 2649.4158 | AE31: 0 | AF31: 1 | AG31: 14.741338 | AH31: 11 | AI31: 0 | AJ31: 0 | AK31: sig. enriched in ATG18 | AL31: =SUM(I31:T31) -> 30128.507 | AM31: =SUM(U31:AC31) -> 0 | AN31: =AL31/#REF!*100 -> #REF! | AO31: =AM31/#REF!*100 -> #REF! | AP31: =AN31/AO31 -> #REF! | AQ31: =LOG(AP31,2) -> #REF! | AR31: =-LOG(AE31,10) -> #NUM! | AT31: =-LOG(AE31, 10)*AG31 -> #NUM!
A32: O77332 | B32: O77332_PLAF7 | C32: PF3D7_0309900 | D32: 0.0030983733 | E32: 5 | F32: 5 | G32: 0 | H32: 239 | I32: 2736.2034 | J32: 2943.7485 | K32: 1662.7882 | L32: 2387.7053 | M32: 2249.4727 | N32: 1295.2657 | P32: 1321.1436 | Q32: 2119.5579 | R32: 4665.8228 | S32: 5992.5747 | T32: 3953.8091 | AE32: 0 | AF32: 1 | AG32: 14.797666 | AH32: 11 | AI32: 0 | AJ32: 0 | AK32: sig. enriched in ATG18 | AL32: =SUM(I32:T32) -> 31328.092 | AM32: =SUM(U32:AC32) -> 0 | AN32: =AL32/#REF!*100 -> #REF! | AO32: =AM32/#REF!*100 -> #REF! | AP32: =AN32/AO32 -> #REF! | AQ32: =LOG(AP32,2) -> #REF! | AR32: =-LOG(AE32,10) -> #NUM! | AT32: =-LOG(AE32, 10)*AG32 -> #NUM!
A33: Q8I5G6 | B33: Q8I5G6_PLAF7 | C33: PF3D7_1225100 | D33: 0.0018013382 | E33: 6 | F33: 6 | G33: 0 | H33: 239 | I33: 3579.9832 | J33: 4851.2339 | K33: 2040.9591 | L33: 1893.9337 | M33: 2218.3022 | N33: 1731.4153 | O33: 1846.3341 | P33: 3490.7971 | Q33: 2864.7847 | R33: 0 | S33: 3714.1807 | T33: 3177.5996 | AE33: 0 | AF33: 1 | AG33: 14.801411 | AH33: 11 | AI33: 0 | AJ33: 0 | AK33: sig. enriched in ATG18 | AL33: =SUM(I33:T33) -> 31409.524 | AM33: =SUM(U33:AC33) -> 0 | AN33: =AL33/#REF!*100 -> #REF! | AO33: =AM33/#REF!*100 -> #REF! | AP33: =AN33/AO33 -> #REF! | AQ33: =LOG(AP33,2) -> #REF! | AR33: =-LOG(AE33,10) -> #NUM! | AT33: =-LOG(AE33, 10)*AG33 -> #NUM!
A34: Q8IM56 | B34: Q8IM56_PLAF7 | C34: PF3D7_1403800 | D34: 0.00082530949 | E34: 10 | F34: 10 | G34: 0 | H34: 262 | I34: 2462.3821 | J34: 2822.2341 | K34: 2174.5354 | L34: 1976.451 | M34: 2395.0945 | N34: 2161.4346 | O34: 2952.0977 | P34: 4221.6099 | Q34: 2560.4397 | R34: 4260.5898 | S34: 3778.3782 | T34: 2517.6387 | AE34: 0 | AF34: 1 | AG34: 14.802167 | AH34: 12 | AI34: 0 | AJ34: 0 | AK34: sig. enriched in ATG18 | AL34: =SUM(I34:T34) -> 34282.886 | AM34: =SUM(U34:AC34) -> 0 | AN34: =AL34/#REF!*100 -> #REF! | AO34: =AM34/#REF!*100 -> #REF! | AP34: =AN34/AO34 -> #REF! | AQ34: =LOG(AP34,2) -> #REF! | AR34: =-LOG(AE34,10) -> #NUM! | AT34: =-LOG(AE34, 10)*AG34 -> #NUM!
A35: Q8I516 | B35: Q8I516_PLAF7 | C35: PF3D7_1241300 | D35: 0.031451613 | E35: 2 | F35: 2 | G35: 0 | H35: 92 | I35: 3065.7175 | J35: 3599.3296 | K35: 2656.6201 | L35: 2539.0303 | M35: 3843.1079 | N35: 1750.1227 | P35: 2028.8517 | Q35: 1870.9515 | R35: 2973.9136 | S35: 2863.5371 | T35: 4939.5239 | AE35: 0 | AF35: 1 | AG35: 14.834162 | AH35: 11 | AI35: 0 | AJ35: 0 | AK35: sig. enriched in ATG18 | AL35: =SUM(I35:T35) -> 32130.706 | AM35: =SUM(U35:AC35) -> 0 | AN35: =AL35/#REF!*100 -> #REF! | AO35: =AM35/#REF!*100 -> #REF! | AP35: =AN35/AO35 -> #REF! | AQ35: =LOG(AP35,2) -> #REF! | AR35: =-LOG(AE35,10) -> #NUM! | AT35: =-LOG(AE35, 10)*AG35 -> #NUM!
A36: Q25817 | B36: Q25817_PLAF7 | C36: rps11 | D36: 0.047291942 | E36: 3 | F36: 3 | G36: 0 | H36: 24 | I36: 3498.929 | J36: 3567.1074 | K36: 2364.2007 | M36: 1897.0692 | N36: 1812.5818 | O36: 3635.5034 | P36: 2295.9629 | Q36: 3119.4548 | R36: 3830.3564 | S36: 3928.6763 | T36: 2303.03 | AE36: 0 | AF36: 1 | AG36: 14.839636 | AH36: 11 | AI36: 0 | AJ36: 0 | AK36: sig. enriched in ATG18 | AL36: =SUM(I36:T36) -> 32252.872 | AM36: =SUM(U36:AC36) -> 0 | AN36: =AL36/#REF!*100 -> #REF! | AO36: =AM36/#REF!*100 -> #REF! | AP36: =AN36/AO36 -> #REF! | AQ36: =LOG(AP36,2) -> #REF! | AR36: =-LOG(AE36,10) -> #NUM! | AT36: =-LOG(AE36, 10)*AG36 -> #NUM!
A37: C0H4K7 | B37: C0H4K7_PLAF7 | C37: PF3D7_0705600 | D37: 0.044050496 | E37: 4 | F37: 4 | G37: 0 | H37: 200 | I37: 2815.6594 | J37: 3175.8792 | L37: 1051.8724 | M37: 4328.1465 | N37: 1532.5117 | O37: 4900.8228 | P37: 3252.1963 | R37: 2187.1453 | S37: 3190.5991 | T37: 2898.8806 | AE37: 0 | AF37: 1 | AG37: 14.840272 | AH37: 10 | AI37: 0 | AJ37: 0 | AK37: sig. enriched in ATG18 | AL37: =SUM(I37:T37) -> 29333.713 | AM37: =SUM(U37:AC37) -> 0 | AN37: =AL37/#REF!*100 -> #REF! | AO37: =AM37/#REF!*100 -> #REF! | AP37: =AN37/AO37 -> #REF! | AQ37: =LOG(AP37,2) -> #REF! | AR37: =-LOG(AE37,10) -> #NUM! | AT37: =-LOG(AE37, 10)*AG37 -> #NUM!
A38: O96130 | B38: O96130_PLAF7 | C38: PF3D7_0202700 | D38: 0.016997168 | E38: 2 | F38: 2 | G38: 0 | H38: 85 | I38: 4248.4399 | J38: 3675.0574 | K38: 2900.0435 | L38: 2220.7275 | M38: 3408.5427 | N38: 1387.4872 | O38: 2654.2122 | P38: 2843.7961 | Q38: 2651.3977 | R38: 3439.8313 | S38: 3694.4685 | T38: 2350.9287 | AE38: 0 | AF38: 1 | AG38: 14.851478 | AH38: 12 | AI38: 0 | AJ38: 0 | AK38: sig. enriched in ATG18 | AL38: =SUM(I38:T38) -> 35474.933 | AM38: =SUM(U38:AC38) -> 0 | AN38: =AL38/#REF!*100 -> #REF! | AO38: =AM38/#REF!*100 -> #REF! | AP38: =AN38/AO38 -> #REF! | AQ38: =LOG(AP38,2) -> #REF! | AR38: =-LOG(AE38,10) -> #NUM! | AT38: =-LOG(AE38, 10)*AG38 -> #NUM!
A39: Q8IAV3 | B39: Q8IAV3_PLAF7 | C39: PF3D7_0811800 | D39: 0.031480975 | E39: 4 | F39: 4 | G39: 0 | H39: 104 | I39: 2632.2742 | J39: 2806.0439 | K39: 2392.8835 | L39: 1359.0663 | M39: 1321.512 | N39: 488.99326 | O39: 4757.6792 | P39: 5482.1782 | Q39: 4059.061 | R39: 4319.5884 | S39: 3249.0911 | T39: 3905.2107 | AE39: 0 | AF39: 1 | AG39: 14.903348 | AH39: 12 | AI39: 0 | AJ39: 0 | AK39: sig. enriched in ATG18 | AL39: =SUM(I39:T39) -> 36773.582 | AM39: =SUM(U39:AC39) -> 0 | AN39: =AL39/#REF!*100 -> #REF! | AO39: =AM39/#REF!*100 -> #REF! | AP39: =AN39/AO39 -> #REF! | AQ39: =LOG(AP39,2) -> #REF! | AR39: =-LOG(AE39,10) -> #NUM! | AT39: =-LOG(AE39, 10)*AG39 -> #NUM!
A40: Q8ILC6 | B40: Q8ILC6_PLAF7 | C40: PF3D7_1433700 | D40: 0.0038333759 | E40: 4 | F40: 4 | G40: 0 | H40: 325 | I40: 2668.7522 | J40: 2586.4624 | K40: 2687.2732 | L40: 2357.7244 | M40: 579.84564 | N40: 2920.0195 | O40: 4945.7197 | P40: 2243.115 | Q40: 3379.7236 | R40: 4242.7949 | S40: 5264.646 | T40: 3433.6819 | AE40: 0 | AF40: 1 | AG40: 14.924231 | AH40: 12 | AI40: 0 | AJ40: 0 | AK40: sig. enriched in ATG18 | AL40: =SUM(I40:T40) -> 37309.758 | AM40: =SUM(U40:AC40) -> 0 | AN40: =AL40/#REF!*100 -> #REF! | AO40: =AM40/#REF!*100 -> #REF! | AP40: =AN40/AO40 -> #REF! | AQ40: =LOG(AP40,2) -> #REF! | AR40: =-LOG(AE40,10) -> #NUM! | AT40: =-LOG(AE40, 10)*AG40 -> #NUM!
...

Sheet Correlation
C1: ATG18 | D1: ATG18 | E1: ATG18 | F1: ATG18 | G1: ATG18 | H1: ATG18 | I1: ATG18 | J1: ATG18 | K1: ATG18 | L1: ATG18 | M1: ATG18 | N1: ATG18 | O1: B11 | P1: B11 | Q1: B11 | R1: B11 | S1: B11 | T1: B11 | U1: B11 | V1: B11 | W1: B11
C2: ATG18_2_1 | D2: ATG18_2_2 | E2: ATG18_2_3 | F2: ATG18_3_1 | G2: ATG18_3_2 | H2: ATG18_3_3 | I2: ATG18_4_1 | J2: ATG18_4_2 | K2: ATG18_4_3 | L2: ATG18_5_1 | M2: ATG18_5_2 | N2: ATG18_5_3 | O2: B11_3_1 | P2: B11_3_2 | Q2: B11_3_3 | R2: B11_4_1 | S2: B11_4_2 | T2: B11_4_3 | U2: B11_5_1 | V2: B11_5_2 | W2: B11_5_3
A3: ATG18 | B3: ATG18_2_1 | C3: =CORREL(INDEX(MaxLFQ_Intensities_processed!$H$2:$AI$3990,0,1+(ROW(C3)-3)), MaxLFQ_Intensities_processed!H2:H3990) -> 1 | D3: =CORREL(INDEX(MaxLFQ_Intensities_processed!$H$2:$AI$3990,0,1+(ROW(D3)-3)), MaxLFQ_Intensities_processed!I2:I3990) -> -0.091864783 | E3: =CORREL(INDEX(MaxLFQ_Intensities_processed!$H$2:$AI$3990,0,1+(ROW(E3)-3)), MaxLFQ_Intensities_processed!J2:J3990) -> -0.090435764 | F3: =CORREL(INDEX(MaxLFQ_Intensities_processed!$H$2:$AI$3990,0,1+(ROW(F3)-3)), MaxLFQ_Intensities_processed!K2:K3990) -> -0.091365925 | G3: =CORREL(INDEX(MaxLFQ_Intensities_processed!$H$2:$AI$3990,0,1+(ROW(G3)-3)), MaxLFQ_Intensities_processed!L2:L3990) -> -0.040255454 | H3: =CORREL(INDEX(MaxLFQ_Intensities_processed!$H$2:$AI$3990,0,1+(ROW(H3)-3)), MaxLFQ_Intensities_processed!M2:M3990) -> -0.039082883 | I3: =CORREL(INDEX(MaxLFQ_Intensities_processed!$H$2:$AI$3990,0,1+(ROW(I3)-3)), MaxLFQ_Intensities_processed!N2:N3990) -> -0.040964429 | J3: =CORREL(INDEX(MaxLFQ_Intensities_processed!$H$2:$AI$3990,0,1+(ROW(J3)-3)), MaxLFQ_Intensities_processed!O2:O3990) -> -0.10920041 | ... W3: =CORREL(INDEX(MaxLFQ_Intensities_processed!$H$2:$AI$3990,0,1+(ROW(W3)-3)), MaxLFQ_Intensities_processed!AB2:AB3990) -> -0.078539836
A4: ATG18 | B4: ATG18_2_2 | C4: =CORREL(INDEX(MaxLFQ_Intensities_processed!$H$2:$AI$3990,0,1+(ROW(C4)-3)), MaxLFQ_Intensities_processed!H2:H3990) -> -0.091864783 | D4: =CORREL(INDEX(MaxLFQ_Intensities_processed!$H$2:$AI$3990,0,1+(ROW(D4)-3)), MaxLFQ_Intensities_processed!I2:I3990) -> 1 | E4: =CORREL(INDEX(MaxLFQ_Intensities_processed!$H$2:$AI$3990,0,1+(ROW(E4)-3)), MaxLFQ_Intensities_processed!J2:J3990) -> 0.99692538 | F4: =CORREL(INDEX(MaxLFQ_Intensities_processed!$H$2:$AI$3990,0,1+(ROW(F4)-3)), MaxLFQ_Intensities_processed!K2:K3990) -> 0.99821316 | G4: =CORREL(INDEX(MaxLFQ_Intensities_processed!$H$2:$AI$3990,0,1+(ROW(G4)-3)), MaxLFQ_Intensities_processed!L2:L3990) -> 0.83187121 | H4: =CORREL(INDEX(MaxLFQ_Intensities_processed!$H$2:$AI$3990,0,1+(ROW(H4)-3)), MaxLFQ_Intensities_processed!M2:M3990) -> 0.83612436 | I4: =CORREL(INDEX(MaxLFQ_Intensities_processed!$H$2:$AI$3990,0,1+(ROW(I4)-3)), MaxLFQ_Intensities_processed!N2:N3990) -> 0.8225011 | J4: =CORREL(INDEX(MaxLFQ_Intensities_processed!$H$2:$AI$3990,0,1+(ROW(J4)-3)), MaxLFQ_Intensities_processed!O2:O3990) -> 0.87195181 | ... W4: =CORREL(INDEX(MaxLFQ_Intensities_processed!$H$2:$AI$3990,0,1+(ROW(W4)-3)), MaxLFQ_Intensities_processed!AB2:AB3990) -> 0.62501526
A5: ATG18 | B5: ATG18_2_3 | C5: =CORREL(INDEX(MaxLFQ_Intensities_processed!$H$2:$AI$3990,0,1+(ROW(C5)-3)), MaxLFQ_Intensities_processed!H2:H3990) -> -0.090435764 | D5: =CORREL(INDEX(MaxLFQ_Intensities_processed!$H$2:$AI$3990,0,1+(ROW(D5)-3)), MaxLFQ_Intensities_processed!I2:I3990) -> 0.99692538 | E5: =CORREL(INDEX(MaxLFQ_Intensities_processed!$H$2:$AI$3990,0,1+(ROW(E5)-3)), MaxLFQ_Intensities_processed!J2:J3990) -> 1 | F5: =CORREL(INDEX(MaxLFQ_Intensities_processed!$H$2:$AI$3990,0,1+(ROW(F5)-3)), MaxLFQ_Intensities_processed!K2:K3990) -> 0.9944561 | G5: =CORREL(INDEX(MaxLFQ_Intensities_processed!$H$2:$AI$3990,0,1+(ROW(G5)-3)), MaxLFQ_Intensities_processed!L2:L3990) -> 0.81573484 | H5: =CORREL(INDEX(MaxLFQ_Intensities_processed!$H$2:$AI$3990,0,1+(ROW(H5)-3)), MaxLFQ_Intensities_processed!M2:M3990) -> 0.82140312 | I5: =CORREL(INDEX(MaxLFQ_Intensities_processed!$H$2:$AI$3990,0,1+(ROW(I5)-3)), MaxLFQ_Intensities_processed!N2:N3990) -> 0.80414322 | J5: =CORREL(INDEX(MaxLFQ_Intensities_processed!$H$2:$AI$3990,0,1+(ROW(J5)-3)), MaxLFQ_Intensities_processed!O2:O3990) -> 0.87887242 | ... W5: =CORREL(INDEX(MaxLFQ_Intensities_processed!$H$2:$AI$3990,0,1+(ROW(W5)-3)), MaxLFQ_Intensities_processed!AB2:AB3990) -> 0.60953324
A6: ATG18 | B6: ATG18_3_1 | C6: =CORREL(INDEX(MaxLFQ_Intensities_processed!$H$2:$AI$3990,0,1+(ROW(C6)-3)), MaxLFQ_Intensities_processed!H2:H3990) -> -0.091365925 | D6: =CORREL(INDEX(MaxLFQ_Intensities_processed!$H$2:$AI$3990,0,1+(ROW(D6)-3)), MaxLFQ_Intensities_processed!I2:I3990) -> 0.99821316 | E6: =CORREL(INDEX(MaxLFQ_Intensities_processed!$H$2:$AI$3990,0,1+(ROW(E6)-3)), MaxLFQ_Intensities_processed!J2:J3990) -> 0.9944561 | F6: =CORREL(INDEX(MaxLFQ_Intensities_processed!$H$2:$AI$3990,0,1+(ROW(F6)-3)), MaxLFQ_Intensities_processed!K2:K3990) -> 1 | G6: =CORREL(INDEX(MaxLFQ_Intensities_processed!$H$2:$AI$3990,0,1+(ROW(G6)-3)), MaxLFQ_Intensities_processed!L2:L3990) -> 0.83140638 | H6: =CORREL(INDEX(MaxLFQ_Intensities_processed!$H$2:$AI$3990,0,1+(ROW(H6)-3)), MaxLFQ_Intensities_processed!M2:M3990) -> 0.83479216 | I6: =CORREL(INDEX(MaxLFQ_Intensities_processed!$H$2:$AI$3990,0,1+(ROW(I6)-3)), MaxLFQ_Intensities_processed!N2:N3990) -> 0.82184797 | J6: =CORREL(INDEX(MaxLFQ_Intensities_processed!$H$2:$AI$3990,0,1+(ROW(J6)-3)), MaxLFQ_Intensities_processed!O2:O3990) -> 0.86901004 | ... W6: =CORREL(INDEX(MaxLFQ_Intensities_processed!$H$2:$AI$3990,0,1+(ROW(W6)-3)), MaxLFQ_Intensities_processed!AB2:AB3990) -> 0.62930556
A7: ATG18 | B7: ATG18_3_2 | C7: =CORREL(INDEX(MaxLFQ_Intensities_processed!$H$2:$AI$3990,0,1+(ROW(C7)-3)), MaxLFQ_Intensities_processed!H2:H3990) -> -0.040255454 | D7: =CORREL(INDEX(MaxLFQ_Intensities_processed!$H$2:$AI$3990,0,1+(ROW(D7)-3)), MaxLFQ_Intensities_processed!I2:I3990) -> 0.83187121 | E7: =CORREL(INDEX(MaxLFQ_Intensities_processed!$H$2:$AI$3990,0,1+(ROW(E7)-3)), MaxLFQ_Intensities_processed!J2:J3990) -> 0.81573484 | F7: =CORREL(INDEX(MaxLFQ_Intensities_processed!$H$2:$AI$3990,0,1+(ROW(F7)-3)), MaxLFQ_Intensities_processed!K2:K3990) -> 0.83140638 | G7: =CORREL(INDEX(MaxLFQ_Intensities_processed!$H$2:$AI$3990,0,1+(ROW(G7)-3)), MaxLFQ_Intensities_processed!L2:L3990) -> 1 | H7: =CORREL(INDEX(MaxLFQ_Intensities_processed!$H$2:$AI$3990,0,1+(ROW(H7)-3)), MaxLFQ_Intensities_processed!M2:M3990) -> 0.99710093 | I7: =CORREL(INDEX(MaxLFQ_Intensities_processed!$H$2:$AI$3990,0,1+(ROW(I7)-3)), MaxLFQ_Intensities_processed!N2:N3990) -> 0.99456618 | J7: =CORREL(INDEX(MaxLFQ_Intensities_processed!$H$2:$AI$3990,0,1+(ROW(J7)-3)), MaxLFQ_Intensities_processed!O2:O3990) -> 0.71302161 | ... W7: =CORREL(INDEX(MaxLFQ_Intensities_processed!$H$2:$AI$3990,0,1+(ROW(W7)-3)), MaxLFQ_Intensities_processed!AB2:AB3990) -> 0.5830877
A8: ATG18 | B8: ATG18_3_3 | C8: =CORREL(INDEX(MaxLFQ_Intensities_processed!$H$2:$AI$3990,0,1+(ROW(C8)-3)), MaxLFQ_Intensities_processed!H2:H3990) -> -0.039082883 | D8: =CORREL(INDEX(MaxLFQ_Intensities_processed!$H$2:$AI$3990,0,1+(ROW(D8)-3)), MaxLFQ_Intensities_processed!I2:I3990) -> 0.83612436 | E8: =CORREL(INDEX(MaxLFQ_Intensities_processed!$H$2:$AI$3990,0,1+(ROW(E8)-3)), MaxLFQ_Intensities_processed!J2:J3990) -> 0.82140312 | F8: =CORREL(INDEX(MaxLFQ_Intensities_processed!$H$2:$AI$3990,0,1+(ROW(F8)-3)), MaxLFQ_Intensities_processed!K2:K3990) -> 0.83479216 | G8: =CORREL(INDEX(MaxLFQ_Intensities_processed!$H$2:$AI$3990,0,1+(ROW(G8)-3)), MaxLFQ_Intensities_processed!L2:L3990) -> 0.99710093 | H8: =CORREL(INDEX(MaxLFQ_Intensities_processed!$H$2:$AI$3990,0,1+(ROW(H8)-3)), MaxLFQ_Intensities_processed!M2:M3990) -> 1 | I8: =CORREL(INDEX(MaxLFQ_Intensities_processed!$H$2:$AI$3990,0,1+(ROW(I8)-3)), MaxLFQ_Intensities_processed!N2:N3990) -> 0.99250367 | J8: =CORREL(INDEX(MaxLFQ_Intensities_processed!$H$2:$AI$3990,0,1+(ROW(J8)-3)), MaxLFQ_Intensities_processed!O2:O3990) -> 0.72103131 | ... W8: =CORREL(INDEX(MaxLFQ_Intensities_processed!$H$2:$AI$3990,0,1+(ROW(W8)-3)), MaxLFQ_Intensities_processed!AB2:AB3990) -> 0.58586782
A9: ATG18 | B9: ATG18_4_1 | C9: =CORREL(INDEX(MaxLFQ_Intensities_processed!$H$2:$AI$3990,0,1+(ROW(C9)-3)), MaxLFQ_Intensities_processed!H2:H3990) -> -0.040964429 | D9: =CORREL(INDEX(MaxLFQ_Intensities_processed!$H$2:$AI$3990,0,1+(ROW(D9)-3)), MaxLFQ_Intensities_processed!I2:I3990) -> 0.8225011 | E9: =CORREL(INDEX(MaxLFQ_Intensities_processed!$H$2:$AI$3990,0,1+(ROW(E9)-3)), MaxLFQ_Intensities_processed!J2:J3990) -> 0.80414322 | F9: =CORREL(INDEX(MaxLFQ_Intensities_processed!$H$2:$AI$3990,0,1+(ROW(F9)-3)), MaxLFQ_Intensities_processed!K2:K3990) -> 0.82184797 | G9: =CORREL(INDEX(MaxLFQ_Intensities_processed!$H$2:$AI$3990,0,1+(ROW(G9)-3)), MaxLFQ_Intensities_processed!L2:L3990) -> 0.99456618 | H9: =CORREL(INDEX(MaxLFQ_Intensities_processed!$H$2:$AI$3990,0,1+(ROW(H9)-3)), MaxLFQ_Intensities_processed!M2:M3990) -> 0.99250367 | I9: =CORREL(INDEX(MaxLFQ_Intensities_processed!$H$2:$AI$3990,0,1+(ROW(I9)-3)), MaxLFQ_Intensities_processed!N2:N3990) -> 1 | J9: =CORREL(INDEX(MaxLFQ_Intensities_processed!$H$2:$AI$3990,0,1+(ROW(J9)-3)), MaxLFQ_Intensities_processed!O2:O3990) -> 0.70194177 | ... W9: =CORREL(INDEX(MaxLFQ_Intensities_processed!$H$2:$AI$3990,0,1+(ROW(W9)-3)), MaxLFQ_Intensities_processed!AB2:AB3990) -> 0.59590442
A10: ATG18 | B10: ATG18_4_2 | C10: =CORREL(INDEX(MaxLFQ_Intensities_processed!$H$2:$AI$3990,0,1+(ROW(C10)-3)), MaxLFQ_Intensities_processed!H2:H3990) -> -0.10920041 | D10: =CORREL(INDEX(MaxLFQ_Intensities_processed!$H$2:$AI$3990,0,1+(ROW(D10)-3)), MaxLFQ_Intensities_processed!I2:I3990) -> 0.87195181 | E10: =CORREL(INDEX(MaxLFQ_Intensities_processed!$H$2:$AI$3990,0,1+(ROW(E10)-3)), MaxLFQ_Intensities_processed!J2:J3990) -> 0.87887242 | F10: =CORREL(INDEX(MaxLFQ_Intensities_processed!$H$2:$AI$3990,0,1+(ROW(F10)-3)), MaxLFQ_Intensities_processed!K2:K3990) -> 0.86901004 | G10: =CORREL(INDEX(MaxLFQ_Intensities_processed!$H$2:$AI$3990,0,1+(ROW(G10)-3)), MaxLFQ_Intensities_processed!L2:L3990) -> 0.71302161 | H10: =CORREL(INDEX(MaxLFQ_Intensities_processed!$H$2:$AI$3990,0,1+(ROW(H10)-3)), MaxLFQ_Intensities_processed!M2:M3990) -> 0.72103131 | I10: =CORREL(INDEX(MaxLFQ_Intensities_processed!$H$2:$AI$3990,0,1+(ROW(I10)-3)), MaxLFQ_Intensities_processed!N2:N3990) -> 0.70194177 | J10: =CORREL(INDEX(MaxLFQ_Intensities_processed!$H$2:$AI$3990,0,1+(ROW(J10)-3)), MaxLFQ_Intensities_processed!O2:O3990) -> 1 | ... W10: =CORREL(INDEX(MaxLFQ_Intensities_processed!$H$2:$AI$3990,0,1+(ROW(W10)-3)), MaxLFQ_Intensities_processed!AB2:AB3990) -> 0.62085308
A11: ATG18 | B11: ATG18_4_3 | C11: =CORREL(INDEX(MaxLFQ_Intensities_processed!$H$2:$AI$3990,0,1+(ROW(C11)-3)), MaxLFQ_Intensities_processed!H2:H3990) -> -0.1055383 | D11: =CORREL(INDEX(MaxLFQ_Intensities_processed!$H$2:$AI$3990,0,1+(ROW(D11)-3)), MaxLFQ_Intensities_processed!I2:I3990) -> 0.85313842 | E11: =CORREL(INDEX(MaxLFQ_Intensities_processed!$H$2:$AI$3990,0,1+(ROW(E11)-3)), MaxLFQ_Intensities_processed!J2:J3990) -> 0.86075837 | F11: =CORREL(INDEX(MaxLFQ_Intensities_processed!$H$2:$AI$3990,0,1+(ROW(F11)-3)), MaxLFQ_Intensities_processed!K2:K3990) -> 0.85012646 | G11: =CORREL(INDEX(MaxLFQ_Intensities_processed!$H$2:$AI$3990,0,1+(ROW(G11)-3)), MaxLFQ_Intensities_processed!L2:L3990) -> 0.68662426 | H11: =CORREL(INDEX(MaxLFQ_Intensities_processed!$H$2:$AI$3990,0,1+(ROW(H11)-3)), MaxLFQ_Intensities_processed!M2:M3990) -> 0.69653743 | I11: =CORREL(INDEX(MaxLFQ_Intensities_processed!$H$2:$AI$3990,0,1+(ROW(I11)-3)), MaxLFQ_Intensities_processed!N2:N3990) -> 0.67621215 | J11: =CORREL(INDEX(MaxLFQ_Intensities_processed!$H$2:$AI$3990,0,1+(ROW(J11)-3)), MaxLFQ_Intensities_processed!O2:O3990) -> 0.99075391 | ... W11: =CORREL(INDEX(MaxLFQ_Intensities_processed!$H$2:$AI$3990,0,1+(ROW(W11)-3)), MaxLFQ_Intensities_processed!AB2:AB3990) -> 0.61437753
A12: ATG18 | B12: ATG18_5_1 | C12: =CORREL(INDEX(MaxLFQ_Intensities_processed!$H$2:$AI$3990,0,1+(ROW(C12)-3)), MaxLFQ_Intensities_processed!H2:H3990) -> -0.1099592 | D12: =CORREL(INDEX(MaxLFQ_Intensities_processed!$H$2:$AI$3990,0,1+(ROW(D12)-3)), MaxLFQ_Intensities_processed!I2:I3990) -> 0.87922458 | E12: =CORREL(INDEX(MaxLFQ_Intensities_processed!$H$2:$AI$3990,0,1+(ROW(E12)-3)), MaxLFQ_Intensities_processed!J2:J3990) -> 0.88455334 | F12: =CORREL(INDEX(MaxLFQ_Intensities_processed!$H$2:$AI$3990,0,1+(ROW(F12)-3)), MaxLFQ_Intensities_processed!K2:K3990) -> 0.87734395 | G12: =CORREL(INDEX(MaxLFQ_Intensities_processed!$H$2:$AI$3990,0,1+(ROW(G12)-3)), MaxLFQ_Intensities_processed!L2:L3990) -> 0.72348554 | H12: =CORREL(INDEX(MaxLFQ_Intensities_processed!$H$2:$AI$3990,0,1+(ROW(H12)-3)), MaxLFQ_Intensities_processed!M2:M3990) -> 0.73208236 | I12: =CORREL(INDEX(MaxLFQ_Intensities_processed!$H$2:$AI$3990,0,1+(ROW(I12)-3)), MaxLFQ_Intensities_processed!N2:N3990) -> 0.71472301 | J12: =CORREL(INDEX(MaxLFQ_Intensities_processed!$H$2:$AI$3990,0,1+(ROW(J12)-3)), MaxLFQ_Intensities_processed!O2:O3990) -> 0.9952342 | ... W12: =CORREL(INDEX(MaxLFQ_Intensities_processed!$H$2:$AI$3990,0,1+(ROW(W12)-3)), MaxLFQ_Intensities_processed!AB2:AB3990) -> 0.64276937
A13: ATG18 | B13: ATG18_5_2 | C13: =CORREL(INDEX(MaxLFQ_Intensities_processed!$H$2:$AI$3990,0,1+(ROW(C13)-3)), MaxLFQ_Intensities_processed!H2:H3990) -> -0.10188822 | D13: =CORREL(INDEX(MaxLFQ_Intensities_processed!$H$2:$AI$3990,0,1+(ROW(D13)-3)), MaxLFQ_Intensities_processed!I2:I3990) -> 0.93942071 | E13: =CORREL(INDEX(MaxLFQ_Intensities_processed!$H$2:$AI$3990,0,1+(ROW(E13)-3)), MaxLFQ_Intensities_processed!J2:J3990) -> 0.9387505 | F13: =CORREL(INDEX(MaxLFQ_Intensities_processed!$H$2:$AI$3990,0,1+(ROW(F13)-3)), MaxLFQ_Intensities_processed!K2:K3990) -> 0.93815617 | G13: =CORREL(INDEX(MaxLFQ_Intensities_processed!$H$2:$AI$3990,0,1+(ROW(G13)-3)), MaxLFQ_Intensities_processed!L2:L3990) -> 0.77599835 | H13: =CORREL(INDEX(MaxLFQ_Intensities_processed!$H$2:$AI$3990,0,1+(ROW(H13)-3)), MaxLFQ_Intensities_processed!M2:M3990) -> 0.78218699 | I13: =CORREL(INDEX(MaxLFQ_Intensities_processed!$H$2:$AI$3990,0,1+(ROW(I13)-3)), MaxLFQ_Intensities_processed!N2:N3990) -> 0.76856192 | J13: =CORREL(INDEX(MaxLFQ_Intensities_processed!$H$2:$AI$3990,0,1+(ROW(J13)-3)), MaxLFQ_Intensities_processed!O2:O3990) -> 0.89008395 | ... W13: =CORREL(INDEX(MaxLFQ_Intensities_processed!$H$2:$AI$3990,0,1+(ROW(W13)-3)), MaxLFQ_Intensities_processed!AB2:AB3990) -> 0.78023277
A14: ATG18 | B14: ATG18_5_3 | C14: =CORREL(INDEX(MaxLFQ_Intensities_processed!$H$2:$AI$3990,0,1+(ROW(C14)-3)), MaxLFQ_Intensities_processed!H2:H3990) -> -0.10315395 | D14: =CORREL(INDEX(MaxLFQ_Intensities_processed!$H$2:$AI$3990,0,1+(ROW(D14)-3)), MaxLFQ_Intensities_processed!I2:I3990) -> 0.93901827 | E14: =CORREL(INDEX(MaxLFQ_Intensities_processed!$H$2:$AI$3990,0,1+(ROW(E14)-3)), MaxLFQ_Intensities_processed!J2:J3990) -> 0.93960734 | F14: =CORREL(INDEX(MaxLFQ_Intensities_processed!$H$2:$AI$3990,0,1+(ROW(F14)-3)), MaxLFQ_Intensities_processed!K2:K3990) -> 0.93665714 | G14: =CORREL(INDEX(MaxLFQ_Intensities_processed!$H$2:$AI$3990,0,1+(ROW(G14)-3)), MaxLFQ_Intensities_processed!L2:L3990) -> 0.7725341 | H14: =CORREL(INDEX(MaxLFQ_Intensities_processed!$H$2:$AI$3990,0,1+(ROW(H14)-3)), MaxLFQ_Intensities_processed!M2:M3990) -> 0.77903896 | I14: =CORREL(INDEX(MaxLFQ_Intensities_processed!$H$2:$AI$3990,0,1+(ROW(I14)-3)), MaxLFQ_Intensities_processed!N2:N3990) -> 0.76261586 | J14: =CORREL(INDEX(MaxLFQ_Intensities_processed!$H$2:$AI$3990,0,1+(ROW(J14)-3)), MaxLFQ_Intensities_processed!O2:O3990) -> 0.89714984 | ... W14: =CORREL(INDEX(MaxLFQ_Intensities_processed!$H$2:$AI$3990,0,1+(ROW(W14)-3)), MaxLFQ_Intensities_processed!AB2:AB3990) -> 0.74725659
A15: B11 | B15: B11_3_1 | C15: =CORREL(INDEX(MaxLFQ_Intensities_processed!$H$2:$AI$3990,0,1+(ROW(C15)-3)), MaxLFQ_Intensities_processed!H2:H3990) -> -0.10272489 | D15: =CORREL(INDEX(MaxLFQ_Intensities_processed!$H$2:$AI$3990,0,1+(ROW(D15)-3)), MaxLFQ_Intensities_processed!I2:I3990) -> 0.94298768 | E15: =CORREL(INDEX(MaxLFQ_Intensities_processed!$H$2:$AI$3990,0,1+(ROW(E15)-3)), MaxLFQ_Intensities_processed!J2:J3990) -> 0.94068747 | F15: =CORREL(INDEX(MaxLFQ_Intensities_processed!$H$2:$AI$3990,0,1+(ROW(F15)-3)), MaxLFQ_Intensities_processed!K2:K3990) -> 0.94252657 | G15: =CORREL(INDEX(MaxLFQ_Intensities_processed!$H$2:$AI$3990,0,1+(ROW(G15)-3)), MaxLFQ_Intensities_processed!L2:L3990) -> 0.78305677 | H15: =CORREL(INDEX(MaxLFQ_Intensities_processed!$H$2:$AI$3990,0,1+(ROW(H15)-3)), MaxLFQ_Intensities_processed!M2:M3990) -> 0.78930799 | I15: =CORREL(INDEX(MaxLFQ_Intensities_processed!$H$2:$AI$3990,0,1+(ROW(I15)-3)), MaxLFQ_Intensities_processed!N2:N3990) -> 0.77529965 | J15: =CORREL(INDEX(MaxLFQ_Intensities_processed!$H$2:$AI$3990,0,1+(ROW(J15)-3)), MaxLFQ_Intensities_processed!O2:O3990) -> 0.88707821 | ... W15: =CORREL(INDEX(MaxLFQ_Intensities_processed!$H$2:$AI$3990,0,1+(ROW(W15)-3)), MaxLFQ_Intensities_processed!AB2:AB3990) -> 0.77730528
A16: B11 | B16: B11_3_2 | C16: =CORREL(INDEX(MaxLFQ_Intensities_processed!$H$2:$AI$3990,0,1+(ROW(C16)-3)), MaxLFQ_Intensities_processed!H2:H3990) -> -0.083813408 | D16: =CORREL(INDEX(MaxLFQ_Intensities_processed!$H$2:$AI$3990,0,1+(ROW(D16)-3)), MaxLFQ_Intensities_processed!I2:I3990) -> 0.67104656 | E16: =CORREL(INDEX(MaxLFQ_Intensities_processed!$H$2:$AI$3990,0,1+(ROW(E16)-3)), MaxLFQ_Intensities_processed!J2:J3990) -> 0.65821828 | F16: =CORREL(INDEX(MaxLFQ_Intensities_processed!$H$2:$AI$3990,0,1+(ROW(F16)-3)), MaxLFQ_Intensities_processed!K2:K3990) -> 0.67325391 | G16: =CORREL(INDEX(MaxLFQ_Intensities_processed!$H$2:$AI$3990,0,1+(ROW(G16)-3)), MaxLFQ_Intensities_processed!L2:L3990) -> 0.61937653 | H16: =CORREL(INDEX(MaxLFQ_Intensities_processed!$H$2:$AI$3990,0,1+(ROW(H16)-3)), MaxLFQ_Intensities_processed!M2:M3990) -> 0.62127841 | I16: =CORREL(INDEX(MaxLFQ_Intensities_processed!$H$2:$AI$3990,0,1+(ROW(I16)-3)), MaxLFQ_Intensities_processed!N2:N3990) -> 0.62039763 | J16: =CORREL(INDEX(MaxLFQ_Intensities_processed!$H$2:$AI$3990,0,1+(ROW(J16)-3)), MaxLFQ_Intensities_processed!O2:O3990) -> 0.65758019 | ... W16: =CORREL(INDEX(MaxLFQ_Intensities_processed!$H$2:$AI$3990,0,1+(ROW(W16)-3)), MaxLFQ_Intensities_processed!AB2:AB3990) -> 0.90273829
A17: B11 | B17: B11_3_3 | C17: =CORREL(INDEX(MaxLFQ_Intensities_processed!$H$2:$AI$3990,0,1+(ROW(C17)-3)), MaxLFQ_Intensities_processed!H2:H3990) -> -0.082028089 | D17: =CORREL(INDEX(MaxLFQ_Intensities_processed!$H$2:$AI$3990,0,1+(ROW(D17)-3)), MaxLFQ_Intensities_processed!I2:I3990) -> 0.66622009 | E17: =CORREL(INDEX(MaxLFQ_Intensities_processed!$H$2:$AI$3990,0,1+(ROW(E17)-3)), MaxLFQ_Intensities_processed!J2:J3990) -> 0.6424531 | F17: =CORREL(INDEX(MaxLFQ_Intensities_processed!$H$2:$AI$3990,0,1+(ROW(F17)-3)), MaxLFQ_Intensities_processed!K2:K3990) -> 0.67127689 | G17: =CORREL(INDEX(MaxLFQ_Intensities_processed!$H$2:$AI$3990,0,1+(ROW(G17)-3)), MaxLFQ_Intensities_processed!L2:L3990) -> 0.61474753 | H17: =CORREL(INDEX(MaxLFQ_Intensities_processed!$H$2:$AI$3990,0,1+(ROW(H17)-3)), MaxLFQ_Intensities_processed!M2:M3990) -> 0.61403811 | I17: =CORREL(INDEX(MaxLFQ_Intensities_processed!$H$2:$AI$3990,0,1+(ROW(I17)-3)), MaxLFQ_Intensities_processed!N2:N3990) -> 0.60860115 | J17: =CORREL(INDEX(MaxLFQ_Intensities_processed!$H$2:$AI$3990,0,1+(ROW(J17)-3)), MaxLFQ_Intensities_processed!O2:O3990) -> 0.64466502 | ... W17: =CORREL(INDEX(MaxLFQ_Intensities_processed!$H$2:$AI$3990,0,1+(ROW(W17)-3)), MaxLFQ_Intensities_processed!AB2:AB3990) -> 0.83195752
A18: B11 | B18: B11_4_1 | C18: =CORREL(INDEX(MaxLFQ_Intensities_processed!$H$2:$AI$3990,0,1+(ROW(C18)-3)), MaxLFQ_Intensities_processed!H2:H3990) -> -0.08368282 | D18: =CORREL(INDEX(MaxLFQ_Intensities_processed!$H$2:$AI$3990,0,1+(ROW(D18)-3)), MaxLFQ_Intensities_processed!I2:I3990) -> 0.66557855 | E18: =CORREL(INDEX(MaxLFQ_Intensities_processed!$H$2:$AI$3990,0,1+(ROW(E18)-3)), MaxLFQ_Intensities_processed!J2:J3990) -> 0.63729426 | F18: =CORREL(INDEX(MaxLFQ_Intensities_processed!$H$2:$AI$3990,0,1+(ROW(F18)-3)), MaxLFQ_Intensities_processed!K2:K3990) -> 0.67315535 | G18: =CORREL(INDEX(MaxLFQ_Intensities_processed!$H$2:$AI$3990,0,1+(ROW(G18)-3)), MaxLFQ_Intensities_processed!L2:L3990) -> 0.62693452 | H18: =CORREL(INDEX(MaxLFQ_Intensities_processed!$H$2:$AI$3990,0,1+(ROW(H18)-3)), MaxLFQ_Intensities_processed!M2:M3990) -> 0.62134337 | I18: =CORREL(INDEX(MaxLFQ_Intensities_processed!$H$2:$AI$3990,0,1+(ROW(I18)-3)), MaxLFQ_Intensities_processed!N2:N3990) -> 0.6312468 | J18: =CORREL(INDEX(MaxLFQ_Intensities_processed!$H$2:$AI$3990,0,1+(ROW(J18)-3)), MaxLFQ_Intensities_processed!O2:O3990) -> 0.62629394 | ... W18: =CORREL(INDEX(MaxLFQ_Intensities_processed!$H$2:$AI$3990,0,1+(ROW(W18)-3)), MaxLFQ_Intensities_processed!AB2:AB3990) -> 0.86904737
A19: B11 | B19: B11_4_2 | C19: =CORREL(INDEX(MaxLFQ_Intensities_processed!$H$2:$AI$3990,0,1+(ROW(C19)-3)), MaxLFQ_Intensities_processed!H2:H3990) -> -0.081441531 | D19: =CORREL(INDEX(MaxLFQ_Intensities_processed!$H$2:$AI$3990,0,1+(ROW(D19)-3)), MaxLFQ_Intensities_processed!I2:I3990) -> 0.64961079 | E19: =CORREL(INDEX(MaxLFQ_Intensities_processed!$H$2:$AI$3990,0,1+(ROW(E19)-3)), MaxLFQ_Intensities_processed!J2:J3990) -> 0.62743909 | F19: =CORREL(INDEX(MaxLFQ_Intensities_processed!$H$2:$AI$3990,0,1+(ROW(F19)-3)), MaxLFQ_Intensities_processed!K2:K3990) -> 0.653643 | G19: =CORREL(INDEX(MaxLFQ_Intensities_processed!$H$2:$AI$3990,0,1+(ROW(G19)-3)), MaxLFQ_Intensities_processed!L2:L3990) -> 0.60080174 | H19: =CORREL(INDEX(MaxLFQ_Intensities_processed!$H$2:$AI$3990,0,1+(ROW(H19)-3)), MaxLFQ_Intensities_processed!M2:M3990) -> 0.60656867 | I19: =CORREL(INDEX(MaxLFQ_Intensities_processed!$H$2:$AI$3990,0,1+(ROW(I19)-3)), MaxLFQ_Intensities_processed!N2:N3990) -> 0.60060394 | J19: =CORREL(INDEX(MaxLFQ_Intensities_processed!$H$2:$AI$3990,0,1+(ROW(J19)-3)), MaxLFQ_Intensities_processed!O2:O3990) -> 0.64863009 | ... W19: =CORREL(INDEX(MaxLFQ_Intensities_processed!$H$2:$AI$3990,0,1+(ROW(W19)-3)), MaxLFQ_Intensities_processed!AB2:AB3990) -> 0.90920136
A20: B11 | B20: B11_4_3 | C20: =CORREL(INDEX(MaxLFQ_Intensities_processed!$H$2:$AI$3990,0,1+(ROW(C20)-3)), MaxLFQ_Intensities_processed!H2:H3990) -> -0.085187707 | D20: =CORREL(INDEX(MaxLFQ_Intensities_processed!$H$2:$AI$3990,0,1+(ROW(D20)-3)), MaxLFQ_Intensities_processed!I2:I3990) -> 0.65429532 | E20: =CORREL(INDEX(MaxLFQ_Intensities_processed!$H$2:$AI$3990,0,1+(ROW(E20)-3)), MaxLFQ_Intensities_processed!J2:J3990) -> 0.63714571 | F20: =CORREL(INDEX(MaxLFQ_Intensities_processed!$H$2:$AI$3990,0,1+(ROW(F20)-3)), MaxLFQ_Intensities_processed!K2:K3990) -> 0.6564426 | G20: =CORREL(INDEX(MaxLFQ_Intensities_processed!$H$2:$AI$3990,0,1+(ROW(G20)-3)), MaxLFQ_Intensities_processed!L2:L3990) -> 0.59984229 | H20: =CORREL(INDEX(MaxLFQ_Intensities_processed!$H$2:$AI$3990,0,1+(ROW(H20)-3)), MaxLFQ_Intensities_processed!M2:M3990) -> 0.60726019 | I20: =CORREL(INDEX(MaxLFQ_Intensities_processed!$H$2:$AI$3990,0,1+(ROW(I20)-3)), MaxLFQ_Intensities_processed!N2:N3990) -> 0.58932386 | J20: =CORREL(INDEX(MaxLFQ_Intensities_processed!$H$2:$AI$3990,0,1+(ROW(J20)-3)), MaxLFQ_Intensities_processed!O2:O3990) -> 0.66436053 | ... W20: =CORREL(INDEX(MaxLFQ_Intensities_processed!$H$2:$AI$3990,0,1+(ROW(W20)-3)), MaxLFQ_Intensities_processed!AB2:AB3990) -> 0.87974542
A21: B11 | B21: B11_5_1 | C21: =CORREL(INDEX(MaxLFQ_Intensities_processed!$H$2:$AI$3990,0,1+(ROW(C21)-3)), MaxLFQ_Intensities_processed!H2:H3990) -> -0.085526635 | D21: =CORREL(INDEX(MaxLFQ_Intensities_processed!$H$2:$AI$3990,0,1+(ROW(D21)-3)), MaxLFQ_Intensities_processed!I2:I3990) -> 0.65277657 | E21: =CORREL(INDEX(MaxLFQ_Intensities_processed!$H$2:$AI$3990,0,1+(ROW(E21)-3)), MaxLFQ_Intensities_processed!J2:J3990) -> 0.63541184 | F21: =CORREL(INDEX(MaxLFQ_Intensities_processed!$H$2:$AI$3990,0,1+(ROW(F21)-3)), MaxLFQ_Intensities_processed!K2:K3990) -> 0.65452808 | G21: =CORREL(INDEX(MaxLFQ_Intensities_processed!$H$2:$AI$3990,0,1+(ROW(G21)-3)), MaxLFQ_Intensities_processed!L2:L3990) -> 0.59506308 | H21: =CORREL(INDEX(MaxLFQ_Intensities_processed!$H$2:$AI$3990,0,1+(ROW(H21)-3)), MaxLFQ_Intensities_processed!M2:M3990) -> 0.60322262 | I21: =CORREL(INDEX(MaxLFQ_Intensities_processed!$H$2:$AI$3990,0,1+(ROW(I21)-3)), MaxLFQ_Intensities_processed!N2:N3990) -> 0.58727735 | J21: =CORREL(INDEX(MaxLFQ_Intensities_processed!$H$2:$AI$3990,0,1+(ROW(J21)-3)), MaxLFQ_Intensities_processed!O2:O3990) -> 0.66550374 | ... W21: =CORREL(INDEX(MaxLFQ_Intensities_processed!$H$2:$AI$3990,0,1+(ROW(W21)-3)), MaxLFQ_Intensities_processed!AB2:AB3990) -> 0.8955714
A22: B11 | B22: B11_5_2 | C22: =CORREL(INDEX(MaxLFQ_Intensities_processed!$H$2:$AI$3990,0,1+(ROW(C22)-3)), MaxLFQ_Intensities_processed!H2:H3990) -> -0.090895089 | D22: =CORREL(INDEX(MaxLFQ_Intensities_processed!$H$2:$AI$3990,0,1+(ROW(D22)-3)), MaxLFQ_Intensities_processed!I2:I3990) -> 0.64517274 | E22: =CORREL(INDEX(MaxLFQ_Intensities_processed!$H$2:$AI$3990,0,1+(ROW(E22)-3)), MaxLFQ_Intensities_processed!J2:J3990) -> 0.636863 | F22: =CORREL(INDEX(MaxLFQ_Intensities_processed!$H$2:$AI$3990,0,1+(ROW(F22)-3)), MaxLFQ_Intensities_processed!K2:K3990) -> 0.64638523 | G22: =CORREL(INDEX(MaxLFQ_Intensities_processed!$H$2:$AI$3990,0,1+(ROW(G22)-3)), MaxLFQ_Intensities_processed!L2:L3990) -> 0.5801141 | H22: =CORREL(INDEX(MaxLFQ_Intensities_processed!$H$2:$AI$3990,0,1+(ROW(H22)-3)), MaxLFQ_Intensities_processed!M2:M3990) -> 0.59121845 | I22: =CORREL(INDEX(MaxLFQ_Intensities_processed!$H$2:$AI$3990,0,1+(ROW(I22)-3)), MaxLFQ_Intensities_processed!N2:N3990) -> 0.57518697 | J22: =CORREL(INDEX(MaxLFQ_Intensities_processed!$H$2:$AI$3990,0,1+(ROW(J22)-3)), MaxLFQ_Intensities_processed!O2:O3990) -> 0.66214732 | ... W22: =CORREL(INDEX(MaxLFQ_Intensities_processed!$H$2:$AI$3990,0,1+(ROW(W22)-3)), MaxLFQ_Intensities_processed!AB2:AB3990) -> 0.9571554
A23: B11 | B23: B11_5_3 | C23: =CORREL(INDEX(MaxLFQ_Intensities_processed!$H$2:$AI$3990,0,1+(ROW(C23)-3)), MaxLFQ_Intensities_processed!H2:H3990) -> -0.078539836 | D23: =CORREL(INDEX(MaxLFQ_Intensities_processed!$H$2:$AI$3990,0,1+(ROW(D23)-3)), MaxLFQ_Intensities_processed!I2:I3990) -> 0.62501526 | E23: =CORREL(INDEX(MaxLFQ_Intensities_processed!$H$2:$AI$3990,0,1+(ROW(E23)-3)), MaxLFQ_Intensities_processed!J2:J3990) -> 0.60953324 | F23: =CORREL(INDEX(MaxLFQ_Intensities_processed!$H$2:$AI$3990,0,1+(ROW(F23)-3)), MaxLFQ_Intensities_processed!K2:K3990) -> 0.62930556 | G23: =CORREL(INDEX(MaxLFQ_Intensities_processed!$H$2:$AI$3990,0,1+(ROW(G23)-3)), MaxLFQ_Intensities_processed!L2:L3990) -> 0.5830877 | H23: =CORREL(INDEX(MaxLFQ_Intensities_processed!$H$2:$AI$3990,0,1+(ROW(H23)-3)), MaxLFQ_Intensities_processed!M2:M3990) -> 0.58586782 | I23: =CORREL(INDEX(MaxLFQ_Intensities_processed!$H$2:$AI$3990,0,1+(ROW(I23)-3)), MaxLFQ_Intensities_processed!N2:N3990) -> 0.59590442 | J23: =CORREL(INDEX(MaxLFQ_Intensities_processed!$H$2:$AI$3990,0,1+(ROW(J23)-3)), MaxLFQ_Intensities_processed!O2:O3990) -> 0.62085308 | ... W23: =CORREL(INDEX(MaxLFQ_Intensities_processed!$H$2:$AI$3990,0,1+(ROW(W23)-3)), MaxLFQ_Intensities_processed!AB2:AB3990) -> 1

Sheet MaxLFQ_Intensities
A1: Protein.Group | B1: Protein.Names | C1: Genes | D1: max_PG.Q.val | E1: max_pep | F1: max_proteotypic_pep | G1: max_shared_pep | H1: max_digested_peptides | I1: ATG18_2_1 | J1: ATG18_2_2 | K1: ATG18_2_3 | L1: ATG18_3_1 | M1: ATG18_3_2 | N1: ATG18_3_3 | O1: ATG18_4_1 | P1: ATG18_4_2 | Q1: ATG18_4_3 | R1: ATG18_5_1 | S1: ATG18_5_2 | T1: ATG18_5_3 | U1: B11_3_1 | V1: B11_3_2 | W1: B11_3_3 | X1: B11_4_1 | Y1: B11_4_2 | Z1: B11_4_3 | AA1: B11_5_1 | AB1: B11_5_2 | AC1: B11_5_3
A2: A0A0H3VB35 | B2: A0A0H3VB35_PLAF7 | C2: cNBP | D2: 0.035665669 | E2: 3 | F2: 3 | G2: 0 | H2: 42 | J2: 4959.9888 | K2: 4234.2393 | L2: 2206.6177 | M2: 3355.2551 | N2: 6417.2451 | O2: 10353.453 | R2: 7223.0361 | S2: 7560.084 | T2: 9933.6533 | Y2: 7389.1616 | Z2: 7344.3296 | AA2: 4489.9292 | AB2: 4919.2534
A3: A0A140KXU9 | B3: A0A140KXU9_PLAF7 | C3: PF3D7_API00100 | D3: 0.027707096 | E3: 5 | F3: 1 | G3: 5 | H3: 42 | I3: 18810.365 | J3: 18616.502 | K3: 15297.423 | L3: 3506.1841 | M3: 6446.9907 | N3: 3337.0569 | O3: 15556.361 | P3: 11581.687 | Q3: 16144.59 | R3: 28084.488 | S3: 23124.348 | T3: 19808.41 | U3: 1252.6899 | W3: 482.46631 | X3: 1577.2607 | Y3: 2451.499 | Z3: 2351.3228 | AA3: 1544.9885 | AB3: 1422.4211 | AC3: 1627.8962
A4: A0A140KXV7;Q25812 | B4: A0A140KXV7_PLAF7;Q25812_PLAF7 | C4: PF3D7_API02000;rpl14 | D4: 0.056099497 | E4: 5 | F4: 0 | G4: 5 | H4: 22 | I4: 21131.691 | J4: 26418.982 | K4: 17857.543 | L4: 4572.9756 | M4: 7807.0127 | N4: 3017.783 | O4: 13332.086 | P4: 9244.3379 | Q4: 11945.857 | R4: 23949.709 | S4: 23097.379 | T4: 20370.477 | W4: 1345.2841 | X4: 1400.1738 | Y4: 1968.0339 | AA4: 1459.6736 | AC4: 1690.085
A5: A0A140KXV8;Q25813 | B5: A0A140KXV8_PLAF7;Q25813_PLAF7 | C5: PF3D7_API02100;rps8 | D5: 0.031476997 | E5: 2 | F5: 0 | G5: 2 | H5: 26 | I5: 6258.248 | J5: 8496.0977 | K5: 6065.8804 | L5: 1312.2844 | M5: 1760.2369 | N5: 524.57477 | O5: 2087.3452 | P5: 2951.8276 | Q5: 2865.2754 | R5: 10091.922 | S5: 10043.606 | T5: 8517.2686 | AA5: 658.35028 | AB5: 334.03467
A6: A0A140KXW0;Q25815 | B6: A0A140KXW0_PLAF7;Q25815_PLAF7 | C6: PF3D7_API02300;rps5 | D6: 0.054606367 | E6: 9 | F6: 0 | G6: 9 | H6: 52 | I6: 18730.588 | J6: 21210.125 | K6: 18743.676 | L6: 7074.3496 | M6: 8322.4258 | N6: 4678.1787 | O6: 16973.248 | P6: 17821.76 | Q6: 17268.596 | R6: 22605.201 | S6: 24021.879 | T6: 19300.688 | W6: 2693.5757 | X6: 469.24304 | Y6: 1306.6527 | Z6: 1089.5593 | AC6: 2903.613
A7: A0A140KXW8 | B7: A0A140KXW8_PLAF7 | C7: PF3D7_API03500 | D7: 0.017489422 | E7: 3 | F7: 1 | G7: 2 | H7: 27 | I7: 8421.0693 | J7: 10737.054 | K7: 10179.279 | M7: 1854.7683 | N7: 1126.0527 | O7: 12454.565 | P7: 11276.992 | Q7: 13495.083 | R7: 19553.809 | S7: 24706.789 | T7: 17662.773 | X7: 1196.2562 | Y7: 1413.7538 | Z7: 1569.9254 | AA7: 1808.3816 | AB7: 1183.3757 | AC7: 2129.4907
A8: A0A140KXW9;Q25823 | B8: A0A140KXW9_PLAF7;Q25823_PLAF7 | C8: Clp;PF3D7_API03600 | D8: 0.0066955495 | E8: 24 | F8: 0 | G8: 24 | H8: 128 | I8: 30222.82 | J8: 36621.93 | K8: 26262.35 | L8: 4722.7739 | M8: 4936.2061 | N8: 3890.5767 | O8: 34932.492 | P8: 34603.613 | Q8: 36003.508 | R8: 56015.293 | S8: 56413.473 | T8: 52207.086 | U8: 1644.9805 | V8: 4029.0859 | W8: 829.92694 | X8: 3004.877 | Y8: 4914.7642 | Z8: 5391.2563 | AA8: 3099.5916 | AB8: 3120.8823 | AC8: 3407.4839
A9: A0A143ZUM0 | B9: A0A143ZUM0_PLAF7 | C9: PF3D7_0107800 | D9: 0.0023384974 | E9: 38 | F9: 38 | G9: 0 | H9: 165 | I9: 30582.117 | J9: 35951.734 | K9: 27500.057 | L9: 27821.645 | M9: 31797.869 | N9: 20665.604 | O9: 45499.824 | P9: 53497.891 | Q9: 46450.129 | R9: 41996.691 | S9: 43972.234 | T9: 37018.629 | X9: 2300.6165 | Y9: 4079.637 | Z9: 4109.6362 | AA9: 4059.0144 | AB9: 4109.1147 | AC9: 3183.8591
A10: A0A143ZV68 | B10: A0A143ZV68_PLAF7 | C10: PF3D7_0314200 | D10: 0.070716888 | E10: 2 | F10: 2 | G10: 0 | H10: 218 | I10: 3513.3838 | K10: 2730.0242 | L10: 2484.5542 | O10: 4175.9663 | P10: 3331.7683 | R10: 3044.2166 | S10: 4846.1826 | T10: 2643.999 | Z10: 2542.9233
A11: A0A143ZVA6;C0H4G3 | B11: A0A143ZVA6_PLAF7;C0H4G3_PLAF7 | C11: PF3D7_0526200.1;PF3D7_0526200.2 | D11: 0.00043308793 | E11: 28 | F11: 0 | G11: 28 | H11: 81 | I11: 28454.027 | J11: 31756.482 | K11: 25264.775 | L11: 6436.7983 | M11: 6649.1333 | N11: 4985.4663 | O11: 46418.863 | P11: 53892.266 | Q11: 41487.695 | R11: 81175.68 | S11: 90234.344 | T11: 73794.281 | U11: 2170.9495 | V11: 2238.1248 | W11: 2019.3412 | X11: 17081.006 | Y11: 25572.205 | Z11: 27945.715 | AA11: 14059.308 | AB11: 9472.3564 | AC11: 15976.684
A12: A0A143ZVB5;C6KT86 | B12: A0A143ZVB5_PLAF7;C6KT86_PLAF7 | C12: PF3D7_0625000.1;PF3D7_0625000.2 | D12: 0.021341464 | E12: 3 | F12: 0 | G12: 3 | H12: 47 | I12: 999.02588 | J12: 2079.5625 | K12: 1219.7877 | O12: 6675.939 | P12: 5668.2056 | Q12: 5780.7808 | R12: 2879.3066 | S12: 5533.2056 | T12: 5609.3374 | X12: 552.43066
A13: A0A143ZVB6 | B13: A0A143ZVB6_PLAF7 | C13: PF3D7_0903600.1 | D13: 0.00043308793 | E13: 44 | F13: 44 | G13: 0 | H13: 146 | I13: 53117.094 | J13: 59393.727 | K13: 42583.238 | L13: 21152.193 | M13: 23598.785 | N13: 19127.609 | O13: 151647.3 | P13: 171691.31 | Q13: 133694.7 | R13: 253586.97 | S13: 293413.91 | T13: 240945.5 | U13: 18632.229 | V13: 17766.836 | W13: 15212.34 | X13: 33204.676 | Y13: 40014.145 | Z13: 48266.043 | AA13: 41457.77 | AB13: 27759.236 | AC13: 35923.695
A14: A0A143ZVC5;Q8I2L0 | B14: A0A143ZVC5_PLAF7;Q8I2L0_PLAF7 | C14: PF3D7_0930400.1;PF3D7_0930400.2 | D14: 0.001894657 | E14: 38 | F14: 0 | G14: 38 | H14: 147 | I14: 41475.004 | J14: 48625.023 | K14: 38127.883 | L14: 28930.434 | M14: 33358.484 | N14: 23869.914 | O14: 44138.699 | P14: 47232.488 | Q14: 47477.855 | R14: 48721.305 | S14: 50977.953 | T14: 46358.191 | U14: 3638.646 | V14: 2878.3809 | W14: 1345.8887 | X14: 6753.9722 | Y14: 11187.489 | Z14: 10373.952 | AA14: 8666.5781 | AB14: 5520.0776 | AC14: 8192.8193
A15: A0A143ZVD1;A0A143ZXH0 | B15: A0A143ZVD1_PLAF7;A0A143ZXH0_PLAF7 | C15: PF3D7_1351800.1;PF3D7_1351800.2 | D15: 0.044307198 | E15: 4 | F15: 0 | G15: 4 | H15: 32 | I15: 6775.6001 | J15: 5999.7773 | K15: 4786.6274 | L15: 2080.3757 | N15: 1642.9185 | O15: 44005.391 | P15: 42519.801 | Q15: 35554.047 | R15: 11352.65 | S15: 12763.244 | T15: 9041.6602 | V15: 1243.4404 | X15: 2994.4197 | Y15: 5294.3145 | Z15: 4374.667 | AA15: 2449.8142 | AB15: 1326.9647 | AC15: 4229.2568
A16: A0A143ZVJ7 | B16: A0A143ZVJ7_PLAF7 | C16: PF3D7_0717600 | D16: 0.00043308793 | E16: 41 | F16: 41 | G16: 0 | H16: 174 | I16: 33470.855 | J16: 38440.75 | K16: 27244.031 | L16: 23064.188 | M16: 28854.936 | N16: 18734.408 | O16: 40359.539 | P16: 48517.289 | Q16: 40087.176 | R16: 45031.875 | S16: 47730.426 | T16: 38344.496 | U16: 4555.5483 | V16: 5725.3853 | W16: 2832.9668 | X16: 5942.3618 | Y16: 7409.4287 | Z16: 8070.6211 | AA16: 5467.4072 | AB16: 4316.6084 | AC16: 6162.6489
A17: A0A143ZVJ8 | B17: A0A143ZVJ8_PLAF7 | C17: PF3D7_0719500 | D17: 0.062438384 | E17: 15 | F17: 15 | G17: 0 | H17: 57 | I17: 24930.35 | J17: 28334.225 | K17: 21589.613 | L17: 11728.721 | M17: 15318.313 | N17: 8700.1152 | O17: 30149.854 | P17: 40638.492 | Q17: 29293.438 | R17: 45183.809 | S17: 45764.98 | T17: 39473.805 | U17: 785.50708 | W17: 1296.8777 | X17: 1512.9047 | Y17: 3378.3887 | Z17: 3761.6467 | AA17: 4286.0981 | AB17: 3073.6411 | AC17: 4779.5571
